Exception in Tkinter callback
Traceback (most recent call last):
  File "D:\ProgramData\Miniconda\lib\tkinter\__init__.py", line 1705, in __call__
    return self.func(*args)
  File "C:\Users\Matth\wyes-ai\interface\Menu.py", line 56, in trainModel
    model = createModel(x_train,y_train)
  File "C:\Users\Matth\wyes-ai\interface\CNN\payload.py", line 76, in createModel
    model.fit(xtrain1, ytrain, epochs=epochs, batch_size=batch_size, verbose=verbose)
  File "D:\ProgramData\Miniconda\lib\site-packages\keras\engine\training.py", line 1154, in fit
    batch_size=batch_size)
  File "D:\ProgramData\Miniconda\lib\site-packages\keras\engine\training.py", line 579, in _standardize_user_data
    exception_prefix='input')
  File "D:\ProgramData\Miniconda\lib\site-packages\keras\engine\training_utils.py", line 109, in standardize_input_data
    str(len(data)) + ' arrays: ' + str(data)[:200] + '...')
ValueError: Error when checking model input: the list of Numpy arrays that you are passing to your model is not the size the model expected. Expected to see 1 array(s), but instead got the following list of 27 arrays: [array([[ 5.92209350e+02, -8.96152736e+01,  7.85070739e+00,
        -1.33718483e+01,  2.67085530e-01, -2.76258688e-02],
       [ 5.92209350e+02, -8.96152736e+01,  7.85070739e+00,
        -1.33718483e+...
